2024-09-20 21:54:28,337 - app - ERROR - Error adding item: (pymysql.err.IntegrityError) (1048, "Column 'purchase_date' cannot be null")
[SQL: INSERT INTO inventory (asset_tag, asset_type, status, brand, model, fa_code, serial_number, operating_system, purchase_date, age, current_owner, previous_owner, warranty_end_date, condition_notes, department, office, country, vendor_location, updated_by, is_deleted, deleted_at, deleted_by) VALUES (%(asset_tag)s, %(asset_type)s, %(status)s, %(brand)s, %(model)s, %(fa_code)s, %(serial_number)s, %(operating_system)s, %(purchase_date)s, %(age)s, %(current_owner)s, %(previous_owner)s, %(warranty_end_date)s, %(condition_notes)s, %(department)s, %(office)s, %(country)s, %(vendor_location)s, %(updated_by)s, %(is_deleted)s, %(deleted_at)s, %(deleted_by)s)]
[parameters: {'asset_tag': '', 'asset_type': 'Laptop', 'status': 'Available', 'brand': 'Lenovo', 'model': '', 'fa_code': '', 'serial_number': 'fwr', 'operating_system': 'Windows', 'purchase_date': None, 'age': 1, 'current_owner': '', 'previous_owner': '', 'warranty_end_date': None, 'condition_notes': '', 'department': 'IT', 'office': 'Mumbai', 'country': 'Singapore', 'vendor_location': 'Mumbai', 'updated_by': 'Admin', 'is_deleted': 0, 'deleted_at': None, 'deleted_by': None}]
(Background on this error at: https://sqlalche.me/e/20/gkpj)
Traceback (most recent call last):
  File "/Users/sameermishra/Library/CloudStorage/OneDrive-CSDC/Apps/Inventory_app/.venv/lib/python3.12/site-packages/sqlalchemy/engine/base.py", line 1967, in _exec_single_context
    self.dialect.do_execute(
  File "/Users/sameermishra/Library/CloudStorage/OneDrive-CSDC/Apps/Inventory_app/.venv/lib/python3.12/site-packages/sqlalchemy/engine/default.py", line 941, in do_execute
    cursor.execute(statement, parameters)
  File "/Users/sameermishra/Library/CloudStorage/OneDrive-CSDC/Apps/Inventory_app/.venv/lib/python3.12/site-packages/pymysql/cursors.py", line 153, in execute
    result = self._query(query)
             ^^^^^^^^^^^^^^^^^^
  File "/Users/sameermishra/Library/CloudStorage/OneDrive-CSDC/Apps/Inventory_app/.venv/lib/python3.12/site-packages/pymysql/cursors.py", line 322, in _query
    conn.query(q)
  File "/Users/sameermishra/Library/CloudStorage/OneDrive-CSDC/Apps/Inventory_app/.venv/lib/python3.12/site-packages/pymysql/connections.py", line 563, in query
    self._affected_rows = self._read_query_result(unbuffered=unbuffered)
                          ^^^^^^^^^^^^^^^^^^^^^^^^^^^^^^^^^^^^^^^^^^^^^^
  File "/Users/sameermishra/Library/CloudStorage/OneDrive-CSDC/Apps/Inventory_app/.venv/lib/python3.12/site-packages/pymysql/connections.py", line 825, in _read_query_result
    result.read()
  File "/Users/sameermishra/Library/CloudStorage/OneDrive-CSDC/Apps/Inventory_app/.venv/lib/python3.12/site-packages/pymysql/connections.py", line 1199, in read
    first_packet = self.connection._read_packet()
                   ^^^^^^^^^^^^^^^^^^^^^^^^^^^^^^
  File "/Users/sameermishra/Library/CloudStorage/OneDrive-CSDC/Apps/Inventory_app/.venv/lib/python3.12/site-packages/pymysql/connections.py", line 775, in _read_packet
    packet.raise_for_error()
  File "/Users/sameermishra/Library/CloudStorage/OneDrive-CSDC/Apps/Inventory_app/.venv/lib/python3.12/site-packages/pymysql/protocol.py", line 219, in raise_for_error
    err.raise_mysql_exception(self._data)
  File "/Users/sameermishra/Library/CloudStorage/OneDrive-CSDC/Apps/Inventory_app/.venv/lib/python3.12/site-packages/pymysql/err.py", line 150, in raise_mysql_exception
    raise errorclass(errno, errval)
pymysql.err.IntegrityError: (1048, "Column 'purchase_date' cannot be null")

The above exception was the direct cause of the following exception:

Traceback (most recent call last):
  File "/Users/sameermishra/Library/CloudStorage/OneDrive-CSDC/Apps/Inventory_app/app/routes/main.py", line 153, in add_item
    db.session.commit()
  File "/Users/sameermishra/Library/CloudStorage/OneDrive-CSDC/Apps/Inventory_app/.venv/lib/python3.12/site-packages/sqlalchemy/orm/scoping.py", line 597, in commit
    return self._proxied.commit()
           ^^^^^^^^^^^^^^^^^^^^^^
  File "/Users/sameermishra/Library/CloudStorage/OneDrive-CSDC/Apps/Inventory_app/.venv/lib/python3.12/site-packages/sqlalchemy/orm/session.py", line 2028, in commit
    trans.commit(_to_root=True)
  File "<string>", line 2, in commit
  File "/Users/sameermishra/Library/CloudStorage/OneDrive-CSDC/Apps/Inventory_app/.venv/lib/python3.12/site-packages/sqlalchemy/orm/state_changes.py", line 139, in _go
    ret_value = fn(self, *arg, **kw)
                ^^^^^^^^^^^^^^^^^^^^
  File "/Users/sameermishra/Library/CloudStorage/OneDrive-CSDC/Apps/Inventory_app/.venv/lib/python3.12/site-packages/sqlalchemy/orm/session.py", line 1313, in commit
    self._prepare_impl()
  File "<string>", line 2, in _prepare_impl
  File "/Users/sameermishra/Library/CloudStorage/OneDrive-CSDC/Apps/Inventory_app/.venv/lib/python3.12/site-packages/sqlalchemy/orm/state_changes.py", line 139, in _go
    ret_value = fn(self, *arg, **kw)
                ^^^^^^^^^^^^^^^^^^^^
  File "/Users/sameermishra/Library/CloudStorage/OneDrive-CSDC/Apps/Inventory_app/.venv/lib/python3.12/site-packages/sqlalchemy/orm/session.py", line 1288, in _prepare_impl
    self.session.flush()
  File "/Users/sameermishra/Library/CloudStorage/OneDrive-CSDC/Apps/Inventory_app/.venv/lib/python3.12/site-packages/sqlalchemy/orm/session.py", line 4352, in flush
    self._flush(objects)
  File "/Users/sameermishra/Library/CloudStorage/OneDrive-CSDC/Apps/Inventory_app/.venv/lib/python3.12/site-packages/sqlalchemy/orm/session.py", line 4487, in _flush
    with util.safe_reraise():
         ^^^^^^^^^^^^^^^^^^^
  File "/Users/sameermishra/Library/CloudStorage/OneDrive-CSDC/Apps/Inventory_app/.venv/lib/python3.12/site-packages/sqlalchemy/util/langhelpers.py", line 146, in __exit__
    raise exc_value.with_traceback(exc_tb)
  File "/Users/sameermishra/Library/CloudStorage/OneDrive-CSDC/Apps/Inventory_app/.venv/lib/python3.12/site-packages/sqlalchemy/orm/session.py", line 4448, in _flush
    flush_context.execute()
  File "/Users/sameermishra/Library/CloudStorage/OneDrive-CSDC/Apps/Inventory_app/.venv/lib/python3.12/site-packages/sqlalchemy/orm/unitofwork.py", line 466, in execute
    rec.execute(self)
  File "/Users/sameermishra/Library/CloudStorage/OneDrive-CSDC/Apps/Inventory_app/.venv/lib/python3.12/site-packages/sqlalchemy/orm/unitofwork.py", line 642, in execute
    util.preloaded.orm_persistence.save_obj(
  File "/Users/sameermishra/Library/CloudStorage/OneDrive-CSDC/Apps/Inventory_app/.venv/lib/python3.12/site-packages/sqlalchemy/orm/persistence.py", line 93, in save_obj
    _emit_insert_statements(
  File "/Users/sameermishra/Library/CloudStorage/OneDrive-CSDC/Apps/Inventory_app/.venv/lib/python3.12/site-packages/sqlalchemy/orm/persistence.py", line 1233, in _emit_insert_statements
    result = connection.execute(
             ^^^^^^^^^^^^^^^^^^^
  File "/Users/sameermishra/Library/CloudStorage/OneDrive-CSDC/Apps/Inventory_app/.venv/lib/python3.12/site-packages/sqlalchemy/engine/base.py", line 1418, in execute
    return meth(
           ^^^^^
  File "/Users/sameermishra/Library/CloudStorage/OneDrive-CSDC/Apps/Inventory_app/.venv/lib/python3.12/site-packages/sqlalchemy/sql/elements.py", line 515, in _execute_on_connection
    return connection._execute_clauseelement(
           ^^^^^^^^^^^^^^^^^^^^^^^^^^^^^^^^^^
  File "/Users/sameermishra/Library/CloudStorage/OneDrive-CSDC/Apps/Inventory_app/.venv/lib/python3.12/site-packages/sqlalchemy/engine/base.py", line 1640, in _execute_clauseelement
    ret = self._execute_context(
          ^^^^^^^^^^^^^^^^^^^^^^
  File "/Users/sameermishra/Library/CloudStorage/OneDrive-CSDC/Apps/Inventory_app/.venv/lib/python3.12/site-packages/sqlalchemy/engine/base.py", line 1846, in _execute_context
    return self._exec_single_context(
           ^^^^^^^^^^^^^^^^^^^^^^^^^^
  File "/Users/sameermishra/Library/CloudStorage/OneDrive-CSDC/Apps/Inventory_app/.venv/lib/python3.12/site-packages/sqlalchemy/engine/base.py", line 1986, in _exec_single_context
    self._handle_dbapi_exception(
  File "/Users/sameermishra/Library/CloudStorage/OneDrive-CSDC/Apps/Inventory_app/.venv/lib/python3.12/site-packages/sqlalchemy/engine/base.py", line 2355, in _handle_dbapi_exception
    raise sqlalchemy_exception.with_traceback(exc_info[2]) from e
  File "/Users/sameermishra/Library/CloudStorage/OneDrive-CSDC/Apps/Inventory_app/.venv/lib/python3.12/site-packages/sqlalchemy/engine/base.py", line 1967, in _exec_single_context
    self.dialect.do_execute(
  File "/Users/sameermishra/Library/CloudStorage/OneDrive-CSDC/Apps/Inventory_app/.venv/lib/python3.12/site-packages/sqlalchemy/engine/default.py", line 941, in do_execute
    cursor.execute(statement, parameters)
  File "/Users/sameermishra/Library/CloudStorage/OneDrive-CSDC/Apps/Inventory_app/.venv/lib/python3.12/site-packages/pymysql/cursors.py", line 153, in execute
    result = self._query(query)
             ^^^^^^^^^^^^^^^^^^
  File "/Users/sameermishra/Library/CloudStorage/OneDrive-CSDC/Apps/Inventory_app/.venv/lib/python3.12/site-packages/pymysql/cursors.py", line 322, in _query
    conn.query(q)
  File "/Users/sameermishra/Library/CloudStorage/OneDrive-CSDC/Apps/Inventory_app/.venv/lib/python3.12/site-packages/pymysql/connections.py", line 563, in query
    self._affected_rows = self._read_query_result(unbuffered=unbuffered)
                          ^^^^^^^^^^^^^^^^^^^^^^^^^^^^^^^^^^^^^^^^^^^^^^
  File "/Users/sameermishra/Library/CloudStorage/OneDrive-CSDC/Apps/Inventory_app/.venv/lib/python3.12/site-packages/pymysql/connections.py", line 825, in _read_query_result
    result.read()
  File "/Users/sameermishra/Library/CloudStorage/OneDrive-CSDC/Apps/Inventory_app/.venv/lib/python3.12/site-packages/pymysql/connections.py", line 1199, in read
    first_packet = self.connection._read_packet()
                   ^^^^^^^^^^^^^^^^^^^^^^^^^^^^^^
  File "/Users/sameermishra/Library/CloudStorage/OneDrive-CSDC/Apps/Inventory_app/.venv/lib/python3.12/site-packages/pymysql/connections.py", line 775, in _read_packet
    packet.raise_for_error()
  File "/Users/sameermishra/Library/CloudStorage/OneDrive-CSDC/Apps/Inventory_app/.venv/lib/python3.12/site-packages/pymysql/protocol.py", line 219, in raise_for_error
    err.raise_mysql_exception(self._data)
  File "/Users/sameermishra/Library/CloudStorage/OneDrive-CSDC/Apps/Inventory_app/.venv/lib/python3.12/site-packages/pymysql/err.py", line 150, in raise_mysql_exception
    raise errorclass(errno, errval)
sqlalchemy.exc.IntegrityError: (pymysql.err.IntegrityError) (1048, "Column 'purchase_date' cannot be null")
[SQL: INSERT INTO inventory (asset_tag, asset_type, status, brand, model, fa_code, serial_number, operating_system, purchase_date, age, current_owner, previous_owner, warranty_end_date, condition_notes, department, office, country, vendor_location, updated_by, is_deleted, deleted_at, deleted_by) VALUES (%(asset_tag)s, %(asset_type)s, %(status)s, %(brand)s, %(model)s, %(fa_code)s, %(serial_number)s, %(operating_system)s, %(purchase_date)s, %(age)s, %(current_owner)s, %(previous_owner)s, %(warranty_end_date)s, %(condition_notes)s, %(department)s, %(office)s, %(country)s, %(vendor_location)s, %(updated_by)s, %(is_deleted)s, %(deleted_at)s, %(deleted_by)s)]
[parameters: {'asset_tag': '', 'asset_type': 'Laptop', 'status': 'Available', 'brand': 'Lenovo', 'model': '', 'fa_code': '', 'serial_number': 'fwr', 'operating_system': 'Windows', 'purchase_date': None, 'age': 1, 'current_owner': '', 'previous_owner': '', 'warranty_end_date': None, 'condition_notes': '', 'department': 'IT', 'office': 'Mumbai', 'country': 'Singapore', 'vendor_location': 'Mumbai', 'updated_by': 'Admin', 'is_deleted': 0, 'deleted_at': None, 'deleted_by': None}]
(Background on this error at: https://sqlalche.me/e/20/gkpj)
